Workbook

Sheet base
A1: pais | B1: fecha | C1: mes_muestra | D1: rank | E1: artist_names | F1: artist_01 | G1: artist_02 | H1: artist_03 | I1: artist_04 | J1: artist_05 | K1: artist_06 | L1: artist_07 | M1: artist_08 | N1: artist_09 | O1: artist_10 | P1: nacionalidad_01 | Q1: nacionalidad_02 | R1: nacionalidad_03 | S1: nacionalidad_04 | T1: nacionalidad_05 | U1: nacionalidad_06 | V1: nacionalidad_07 | W1: nacionalidad_08 | X1: nacionalidad_09 | Y1: nacionalidad_10 | Z1: track_name | AA1: source | AB1: peak_rank | AC1: previous_rank | AD1: weeks_on_chart | AE1: streams
A2: Argentina | B2: 45967 | C2: noviembre_2025 | D2: 1 | E2: Roze Oficial, Max Carra, Valen, RAMKY EN LOS CONTROLES | F2: Roze Oficial | G2: Max Carra | H2: Valen | I2: RAMKY EN LOS CONTROLES | J2: NA | K2: NA | L2: NA | M2: NA | N2: NA | O2: NA | P2: =IF(F2="NA","NA",_xlfn.XLOOKUP(TRIM(F2),nacionalidad!A:A,nacionalidad!B:B,"Por verificar")) -> Argentina | Q2: =IF(G2="NA","NA",_xlfn.XLOOKUP(TRIM(G2),nacionalidad!A:A,nacionalidad!B:B,"Por verificar")) -> Argentina | R2: =IF(H2="NA","NA",_xlfn.XLOOKUP(TRIM(H2),nacionalidad!A:A,nacionalidad!B:B,"Por verificar")) -> Argentina | S2: =IF(I2="NA","NA",_xlfn.XLOOKUP(TRIM(I2),nacionalidad!A:A,nacionalidad!B:B,"Por verificar")) -> Argentina | T2: =IF(J2="NA","NA",_xlfn.XLOOKUP(TRIM(J2),nacionalidad!A:A,nacionalidad!B:B,"Por verificar")) -> NA | U2: =IF(K2="NA","NA",_xlfn.XLOOKUP(TRIM(K2),nacionalidad!A:A,nacionalidad!B:B,"Por verificar")) -> NA | V2: =IF(L2="NA","NA",_xlfn.XLOOKUP(TRIM(L2),nacionalidad!A:A,nacionalidad!B:B,"Por verificar")) -> NA | W2: =IF(M2="NA","NA",_xlfn.XLOOKUP(TRIM(M2),nacionalidad!A:A,nacionalidad!B:B,"Por verificar")) -> NA | ... Y2: =IF(O2="NA","NA",_xlfn.XLOOKUP(TRIM(O2),nacionalidad!A:A,nacionalidad!B:B,"Por verificar")) -> NA | Z2: Tu jardín con enanitos | AA2: Sony Music Uruguay | AB2: 1 | AC2: 1 | AD2: 24 | AE2: 2468159
A3: Argentina | B3: 45967 | C3: noviembre_2025 | D3: 2 | E3: Young Cister, Kreamly | F3: Young Cister | G3: Kreamly | H3: NA | I3: NA | J3: NA | K3: NA | L3: NA | M3: NA | N3: NA | O3: NA | P3: =IF(F3="NA","NA",_xlfn.XLOOKUP(TRIM(F3),nacionalidad!A:A,nacionalidad!B:B,"Por verificar")) -> Chile | Q3: =IF(G3="NA","NA",_xlfn.XLOOKUP(TRIM(G3),nacionalidad!A:A,nacionalidad!B:B,"Por verificar")) -> Chile | R3: =IF(H3="NA","NA",_xlfn.XLOOKUP(TRIM(H3),nacionalidad!A:A,nacionalidad!B:B,"Por verificar")) -> NA | S3: =IF(I3="NA","NA",_xlfn.XLOOKUP(TRIM(I3),nacionalidad!A:A,nacionalidad!B:B,"Por verificar")) -> NA | T3: =IF(J3="NA","NA",_xlfn.XLOOKUP(TRIM(J3),nacionalidad!A:A,nacionalidad!B:B,"Por verificar")) -> NA | U3: =IF(K3="NA","NA",_xlfn.XLOOKUP(TRIM(K3),nacionalidad!A:A,nacionalidad!B:B,"Por verificar")) -> NA | V3: =IF(L3="NA","NA",_xlfn.XLOOKUP(TRIM(L3),nacionalidad!A:A,nacionalidad!B:B,"Por verificar")) -> NA | W3: =IF(M3="NA","NA",_xlfn.XLOOKUP(TRIM(M3),nacionalidad!A:A,nacionalidad!B:B,"Por verificar")) -> NA | ... Y3: =IF(O3="NA","NA",_xlfn.XLOOKUP(TRIM(O3),nacionalidad!A:A,nacionalidad!B:B,"Por verificar")) -> NA | Z3: QLOO* | AA3: Sony Music Entertainment Chile S.A | AB3: 2 | AC3: 2 | AD3: 19 | AE3: 1671001
A4: Argentina | B4: 45967 | C4: noviembre_2025 | D4: 3 | E4: Rels B | F4: Rels B | G4: NA | H4: NA | I4: NA | J4: NA | K4: NA | L4: NA | M4: NA | N4: NA | O4: NA | P4: =IF(F4="NA","NA",_xlfn.XLOOKUP(TRIM(F4),nacionalidad!A:A,nacionalidad!B:B,"Por verificar")) -> España | Q4: =IF(G4="NA","NA",_xlfn.XLOOKUP(TRIM(G4),nacionalidad!A:A,nacionalidad!B:B,"Por verificar")) -> NA | R4: =IF(H4="NA","NA",_xlfn.XLOOKUP(TRIM(H4),nacionalidad!A:A,nacionalidad!B:B,"Por verificar")) -> NA | S4: =IF(I4="NA","NA",_xlfn.XLOOKUP(TRIM(I4),nacionalidad!A:A,nacionalidad!B:B,"Por verificar")) -> NA | T4: =IF(J4="NA","NA",_xlfn.XLOOKUP(TRIM(J4),nacionalidad!A:A,nacionalidad!B:B,"Por verificar")) -> NA | U4: =IF(K4="NA","NA",_xlfn.XLOOKUP(TRIM(K4),nacionalidad!A:A,nacionalidad!B:B,"Por verificar")) -> NA | V4: =IF(L4="NA","NA",_xlfn.XLOOKUP(TRIM(L4),nacionalidad!A:A,nacionalidad!B:B,"Por verificar")) -> NA | W4: =IF(M4="NA","NA",_xlfn.XLOOKUP(TRIM(M4),nacionalidad!A:A,nacionalidad!B:B,"Por verificar")) -> NA | ... Y4: =IF(O4="NA","NA",_xlfn.XLOOKUP(TRIM(O4),nacionalidad!A:A,nacionalidad!B:B,"Por verificar")) -> NA | Z4: TU VAS SIN (fav) | AA4: DALE PLAY Records / Flakk Team | AB4: 3 | AC4: 3 | AD4: 16 | AE4: 1522062
A5: Argentina | B5: 45967 | C5: noviembre_2025 | D5: 4 | E5: Ovy On The Drums, Quevedo, Beéle | F5: Ovy On The Drums | G5: Quevedo | H5: Beéle | I5: NA | J5: NA | K5: NA | L5: NA | M5: NA | N5: NA | O5: NA | P5: =IF(F5="NA","NA",_xlfn.XLOOKUP(TRIM(F5),nacionalidad!A:A,nacionalidad!B:B,"Por verificar")) -> Colombia | Q5: =IF(G5="NA","NA",_xlfn.XLOOKUP(TRIM(G5),nacionalidad!A:A,nacionalidad!B:B,"Por verificar")) -> España | R5: =IF(H5="NA","NA",_xlfn.XLOOKUP(TRIM(H5),nacionalidad!A:A,nacionalidad!B:B,"Por verificar")) -> Colombia | S5: =IF(I5="NA","NA",_xlfn.XLOOKUP(TRIM(I5),nacionalidad!A:A,nacionalidad!B:B,"Por verificar")) -> NA | T5: =IF(J5="NA","NA",_xlfn.XLOOKUP(TRIM(J5),nacionalidad!A:A,nacionalidad!B:B,"Por verificar")) -> NA | U5: =IF(K5="NA","NA",_xlfn.XLOOKUP(TRIM(K5),nacionalidad!A:A,nacionalidad!B:B,"Por verificar")) -> NA | V5: =IF(L5="NA","NA",_xlfn.XLOOKUP(TRIM(L5),nacionalidad!A:A,nacionalidad!B:B,"Por verificar")) -> NA | W5: =IF(M5="NA","NA",_xlfn.XLOOKUP(TRIM(M5),nacionalidad!A:A,nacionalidad!B:B,"Por verificar")) -> NA | ... Y5: =IF(O5="NA","NA",_xlfn.XLOOKUP(TRIM(O5),nacionalidad!A:A,nacionalidad!B:B,"Por verificar")) -> NA | Z5: YO y TÚ | AA5: WEA Latina | AB5: 4 | AC5: 7 | AD5: 21 | AE5: 1388321
A6: Argentina | B6: 45967 | C6: noviembre_2025 | D6: 5 | E6: Jere Klein, Katteyes, Mateo on the Beatz | F6: Jere Klein | G6: Katteyes | H6: Mateo on the Beatz | I6: NA | J6: NA | K6: NA | L6: NA | M6: NA | N6: NA | O6: NA | P6: =IF(F6="NA","NA",_xlfn.XLOOKUP(TRIM(F6),nacionalidad!A:A,nacionalidad!B:B,"Por verificar")) -> Chile | Q6: =IF(G6="NA","NA",_xlfn.XLOOKUP(TRIM(G6),nacionalidad!A:A,nacionalidad!B:B,"Por verificar")) -> Chile | R6: =IF(H6="NA","NA",_xlfn.XLOOKUP(TRIM(H6),nacionalidad!A:A,nacionalidad!B:B,"Por verificar")) -> Chile | S6: =IF(I6="NA","NA",_xlfn.XLOOKUP(TRIM(I6),nacionalidad!A:A,nacionalidad!B:B,"Por verificar")) -> NA | T6: =IF(J6="NA","NA",_xlfn.XLOOKUP(TRIM(J6),nacionalidad!A:A,nacionalidad!B:B,"Por verificar")) -> NA | U6: =IF(K6="NA","NA",_xlfn.XLOOKUP(TRIM(K6),nacionalidad!A:A,nacionalidad!B:B,"Por verificar")) -> NA | V6: =IF(L6="NA","NA",_xlfn.XLOOKUP(TRIM(L6),nacionalidad!A:A,nacionalidad!B:B,"Por verificar")) -> NA | W6: =IF(M6="NA","NA",_xlfn.XLOOKUP(TRIM(M6),nacionalidad!A:A,nacionalidad!B:B,"Por verificar")) -> NA | ... Y6: =IF(O6="NA","NA",_xlfn.XLOOKUP(TRIM(O6),nacionalidad!A:A,nacionalidad!B:B,"Por verificar")) -> NA | Z6: TODO KE VER | AA6: 2025 JERE KLEIN | AB6: 3 | AC6: 5 | AD6: 12 | AE6: 1339339
A7: Argentina | B7: 45967 | C7: noviembre_2025 | D7: 6 | E7: Milo j | F7: Milo j | G7: NA | H7: NA | I7: NA | J7: NA | K7: NA | L7: NA | M7: NA | N7: NA | O7: NA | P7: =IF(F7="NA","NA",_xlfn.XLOOKUP(TRIM(F7),nacionalidad!A:A,nacionalidad!B:B,"Por verificar")) -> Argentina | Q7: =IF(G7="NA","NA",_xlfn.XLOOKUP(TRIM(G7),nacionalidad!A:A,nacionalidad!B:B,"Por verificar")) -> NA | R7: =IF(H7="NA","NA",_xlfn.XLOOKUP(TRIM(H7),nacionalidad!A:A,nacionalidad!B:B,"Por verificar")) -> NA | S7: =IF(I7="NA","NA",_xlfn.XLOOKUP(TRIM(I7),nacionalidad!A:A,nacionalidad!B:B,"Por verificar")) -> NA | T7: =IF(J7="NA","NA",_xlfn.XLOOKUP(TRIM(J7),nacionalidad!A:A,nacionalidad!B:B,"Por verificar")) -> NA | U7: =IF(K7="NA","NA",_xlfn.XLOOKUP(TRIM(K7),nacionalidad!A:A,nacionalidad!B:B,"Por verificar")) -> NA | V7: =IF(L7="NA","NA",_xlfn.XLOOKUP(TRIM(L7),nacionalidad!A:A,nacionalidad!B:B,"Por verificar")) -> NA | W7: =IF(M7="NA","NA",_xlfn.XLOOKUP(TRIM(M7),nacionalidad!A:A,nacionalidad!B:B,"Por verificar")) -> NA | ... Y7: =IF(O7="NA","NA",_xlfn.XLOOKUP(TRIM(O7),nacionalidad!A:A,nacionalidad!B:B,"Por verificar")) -> NA | Z7: Niño | AA7: Sony Music Latin | AB7: 6 | AC7: 6 | AD7: 6 | AE7: 1289728
A8: Argentina | B8: 45967 | C8: noviembre_2025 | D8: 7 | E8: W Sound, Beéle, Ovy On The Drums | F8: W Sound | G8: Beéle | H8: Ovy On The Drums | I8: NA | J8: NA | K8: NA | L8: NA | M8: NA | N8: NA | O8: NA | P8: =IF(F8="NA","NA",_xlfn.XLOOKUP(TRIM(F8),nacionalidad!A:A,nacionalidad!B:B,"Por verificar")) -> Colombia | Q8: =IF(G8="NA","NA",_xlfn.XLOOKUP(TRIM(G8),nacionalidad!A:A,nacionalidad!B:B,"Por verificar")) -> Colombia | R8: =IF(H8="NA","NA",_xlfn.XLOOKUP(TRIM(H8),nacionalidad!A:A,nacionalidad!B:B,"Por verificar")) -> Colombia | S8: =IF(I8="NA","NA",_xlfn.XLOOKUP(TRIM(I8),nacionalidad!A:A,nacionalidad!B:B,"Por verificar")) -> NA | T8: =IF(J8="NA","NA",_xlfn.XLOOKUP(TRIM(J8),nacionalidad!A:A,nacionalidad!B:B,"Por verificar")) -> NA | U8: =IF(K8="NA","NA",_xlfn.XLOOKUP(TRIM(K8),nacionalidad!A:A,nacionalidad!B:B,"Por verificar")) -> NA | V8: =IF(L8="NA","NA",_xlfn.XLOOKUP(TRIM(L8),nacionalidad!A:A,nacionalidad!B:B,"Por verificar")) -> NA | W8: =IF(M8="NA","NA",_xlfn.XLOOKUP(TRIM(M8),nacionalidad!A:A,nacionalidad!B:B,"Por verificar")) -> NA | ... Y8: =IF(O8="NA","NA",_xlfn.XLOOKUP(TRIM(O8),nacionalidad!A:A,nacionalidad!B:B,"Por verificar")) -> NA | Z8: La Plena - W Sound 05 | AA8: WEA Latina | AB8: 1 | AC8: 4 | AD8: 36 | AE8: 1259847
A9: Argentina | B9: 45967 | C9: noviembre_2025 | D9: 8 | E9: Luck Ra, Miranda! | F9: Luck Ra | G9: Miranda! | H9: NA | I9: NA | J9: NA | K9: NA | L9: NA | M9: NA | N9: NA | O9: NA | P9: =IF(F9="NA","NA",_xlfn.XLOOKUP(TRIM(F9),nacionalidad!A:A,nacionalidad!B:B,"Por verificar")) -> Argentina | Q9: =IF(G9="NA","NA",_xlfn.XLOOKUP(TRIM(G9),nacionalidad!A:A,nacionalidad!B:B,"Por verificar")) -> Argentina | R9: =IF(H9="NA","NA",_xlfn.XLOOKUP(TRIM(H9),nacionalidad!A:A,nacionalidad!B:B,"Por verificar")) -> NA | S9: =IF(I9="NA","NA",_xlfn.XLOOKUP(TRIM(I9),nacionalidad!A:A,nacionalidad!B:B,"Por verificar")) -> NA | T9: =IF(J9="NA","NA",_xlfn.XLOOKUP(TRIM(J9),nacionalidad!A:A,nacionalidad!B:B,"Por verificar")) -> NA | U9: =IF(K9="NA","NA",_xlfn.XLOOKUP(TRIM(K9),nacionalidad!A:A,nacionalidad!B:B,"Por verificar")) -> NA | V9: =IF(L9="NA","NA",_xlfn.XLOOKUP(TRIM(L9),nacionalidad!A:A,nacionalidad!B:B,"Por verificar")) -> NA | W9: =IF(M9="NA","NA",_xlfn.XLOOKUP(TRIM(M9),nacionalidad!A:A,nacionalidad!B:B,"Por verificar")) -> NA | ... Y9: =IF(O9="NA","NA",_xlfn.XLOOKUP(TRIM(O9),nacionalidad!A:A,nacionalidad!B:B,"Por verificar")) -> NA | Z9: TU MISTERIOSO ALGUIEN (CUARTETO) (feat. Miranda!) | AA9: Sony Music Latin | AB9: 2 | AC9: 10 | AD9: 8 | AE9: 1145166
A10: Argentina | B10: 45967 | C10: noviembre_2025 | D10: 9 | E10: Maria Becerra, TINI, XROSS | F10: Maria Becerra | G10: TINI | H10: XROSS | I10: NA | J10: NA | K10: NA | L10: NA | M10: NA | N10: NA | O10: NA | P10: =IF(F10="NA","NA",_xlfn.XLOOKUP(TRIM(F10),nacionalidad!A:A,nacionalidad!B:B,"Por verificar")) -> Argentina | Q10: =IF(G10="NA","NA",_xlfn.XLOOKUP(TRIM(G10),nacionalidad!A:A,nacionalidad!B:B,"Por verificar")) -> Argentina | R10: =IF(H10="NA","NA",_xlfn.XLOOKUP(TRIM(H10),nacionalidad!A:A,nacionalidad!B:B,"Por verificar")) -> Argentina | S10: =IF(I10="NA","NA",_xlfn.XLOOKUP(TRIM(I10),nacionalidad!A:A,nacionalidad!B:B,"Por verificar")) -> NA | T10: =IF(J10="NA","NA",_xlfn.XLOOKUP(TRIM(J10),nacionalidad!A:A,nacionalidad!B:B,"Por verificar")) -> NA | U10: =IF(K10="NA","NA",_xlfn.XLOOKUP(TRIM(K10),nacionalidad!A:A,nacionalidad!B:B,"Por verificar")) -> NA | V10: =IF(L10="NA","NA",_xlfn.XLOOKUP(TRIM(L10),nacionalidad!A:A,nacionalidad!B:B,"Por verificar")) -> NA | W10: =IF(M10="NA","NA",_xlfn.XLOOKUP(TRIM(M10),nacionalidad!A:A,nacionalidad!B:B,"Por verificar")) -> NA | ... Y10: =IF(O10="NA","NA",_xlfn.XLOOKUP(TRIM(O10),nacionalidad!A:A,nacionalidad!B:B,"Por verificar")) -> NA | Z10: HASTA QUE ME ENAMORO | AA10: WEA Latina | AB10: 9 | AC10: 24 | AD10: 7 | AE10: 1144903
A11: Argentina | B11: 45967 | C11: noviembre_2025 | D11: 10 | E11: Easykid, Dysbit | F11: Easykid | G11: Dysbit | H11: NA | I11: NA | J11: NA | K11: NA | L11: NA | M11: NA | N11: NA | O11: NA | P11: =IF(F11="NA","NA",_xlfn.XLOOKUP(TRIM(F11),nacionalidad!A:A,nacionalidad!B:B,"Por verificar")) -> Chile | Q11: =IF(G11="NA","NA",_xlfn.XLOOKUP(TRIM(G11),nacionalidad!A:A,nacionalidad!B:B,"Por verificar")) -> Chile | R11: =IF(H11="NA","NA",_xlfn.XLOOKUP(TRIM(H11),nacionalidad!A:A,nacionalidad!B:B,"Por verificar")) -> NA | S11: =IF(I11="NA","NA",_xlfn.XLOOKUP(TRIM(I11),nacionalidad!A:A,nacionalidad!B:B,"Por verificar")) -> NA | T11: =IF(J11="NA","NA",_xlfn.XLOOKUP(TRIM(J11),nacionalidad!A:A,nacionalidad!B:B,"Por verificar")) -> NA | U11: =IF(K11="NA","NA",_xlfn.XLOOKUP(TRIM(K11),nacionalidad!A:A,nacionalidad!B:B,"Por verificar")) -> NA | V11: =IF(L11="NA","NA",_xlfn.XLOOKUP(TRIM(L11),nacionalidad!A:A,nacionalidad!B:B,"Por verificar")) -> NA | W11: =IF(M11="NA","NA",_xlfn.XLOOKUP(TRIM(M11),nacionalidad!A:A,nacionalidad!B:B,"Por verificar")) -> NA | ... Y11: =IF(O11="NA","NA",_xlfn.XLOOKUP(TRIM(O11),nacionalidad!A:A,nacionalidad!B:B,"Por verificar")) -> NA | Z11: Shiny | AA11: Easykid | AB11: 6 | AC11: 9 | AD11: 9 | AE11: 1137150
A12: Argentina | B12: 45967 | C12: noviembre_2025 | D12: 11 | E12: Myke Towers, Quevedo | F12: Myke Towers | G12: Quevedo | H12: NA | I12: NA | J12: NA | K12: NA | L12: NA | M12: NA | N12: NA | O12: NA | P12: =IF(F12="NA","NA",_xlfn.XLOOKUP(TRIM(F12),nacionalidad!A:A,nacionalidad!B:B,"Por verificar")) -> Puerto Rico | Q12: =IF(G12="NA","NA",_xlfn.XLOOKUP(TRIM(G12),nacionalidad!A:A,nacionalidad!B:B,"Por verificar")) -> España | R12: =IF(H12="NA","NA",_xlfn.XLOOKUP(TRIM(H12),nacionalidad!A:A,nacionalidad!B:B,"Por verificar")) -> NA | S12: =IF(I12="NA","NA",_xlfn.XLOOKUP(TRIM(I12),nacionalidad!A:A,nacionalidad!B:B,"Por verificar")) -> NA | T12: =IF(J12="NA","NA",_xlfn.XLOOKUP(TRIM(J12),nacionalidad!A:A,nacionalidad!B:B,"Por verificar")) -> NA | U12: =IF(K12="NA","NA",_xlfn.XLOOKUP(TRIM(K12),nacionalidad!A:A,nacionalidad!B:B,"Por verificar")) -> NA | V12: =IF(L12="NA","NA",_xlfn.XLOOKUP(TRIM(L12),nacionalidad!A:A,nacionalidad!B:B,"Por verificar")) -> NA | W12: =IF(M12="NA","NA",_xlfn.XLOOKUP(TRIM(M12),nacionalidad!A:A,nacionalidad!B:B,"Por verificar")) -> NA | ... Y12: =IF(O12="NA","NA",_xlfn.XLOOKUP(TRIM(O12),nacionalidad!A:A,nacionalidad!B:B,"Por verificar")) -> NA | Z12: SOLEAO | AA12: WEA Latina | AB12: 4 | AC12: 11 | AD12: 23 | AE12: 1075097
A13: Argentina | B13: 45967 | C13: noviembre_2025 | D13: 12 | E13: Miranda! | F13: Miranda! | G13: NA | H13: NA | I13: NA | J13: NA | K13: NA | L13: NA | M13: NA | N13: NA | O13: NA | P13: =IF(F13="NA","NA",_xlfn.XLOOKUP(TRIM(F13),nacionalidad!A:A,nacionalidad!B:B,"Por verificar")) -> Argentina | Q13: =IF(G13="NA","NA",_xlfn.XLOOKUP(TRIM(G13),nacionalidad!A:A,nacionalidad!B:B,"Por verificar")) -> NA | R13: =IF(H13="NA","NA",_xlfn.XLOOKUP(TRIM(H13),nacionalidad!A:A,nacionalidad!B:B,"Por verificar")) -> NA | S13: =IF(I13="NA","NA",_xlfn.XLOOKUP(TRIM(I13),nacionalidad!A:A,nacionalidad!B:B,"Por verificar")) -> NA | T13: =IF(J13="NA","NA",_xlfn.XLOOKUP(TRIM(J13),nacionalidad!A:A,nacionalidad!B:B,"Por verificar")) -> NA | U13: =IF(K13="NA","NA",_xlfn.XLOOKUP(TRIM(K13),nacionalidad!A:A,nacionalidad!B:B,"Por verificar")) -> NA | V13: =IF(L13="NA","NA",_xlfn.XLOOKUP(TRIM(L13),nacionalidad!A:A,nacionalidad!B:B,"Por verificar")) -> NA | W13: =IF(M13="NA","NA",_xlfn.XLOOKUP(TRIM(M13),nacionalidad!A:A,nacionalidad!B:B,"Por verificar")) -> NA | ... Y13: =IF(O13="NA","NA",_xlfn.XLOOKUP(TRIM(O13),nacionalidad!A:A,nacionalidad!B:B,"Por verificar")) -> NA | Z13: Tu Misterioso Alguien | AA13: Pelo Music | AB13: 1 | AC13: 12 | AD13: 17 | AE13: 1059313
... A29: Argentina | B29: 45967 | C29: noviembre_2025 | D29: 28 | E29: Milo j, Trueno | F29: Milo j | G29: Trueno | H29: NA | I29: NA | J29: NA | K29: NA | L29: NA | M29: NA | N29: NA | O29: NA | P29: =IF(F29="NA","NA",_xlfn.XLOOKUP(TRIM(F29),nacionalidad!A:A,nacionalidad!B:B,"Por verificar")) -> Argentina | Q29: =IF(G29="NA","NA",_xlfn.XLOOKUP(TRIM(G29),nacionalidad!A:A,nacionalidad!B:B,"Por verificar")) -> Argentina | R29: =IF(H29="NA","NA",_xlfn.XLOOKUP(TRIM(H29),nacionalidad!A:A,nacionalidad!B:B,"Por verificar")) -> NA | S29: =IF(I29="NA","NA",_xlfn.XLOOKUP(TRIM(I29),nacionalidad!A:A,nacionalidad!B:B,"Por verificar")) -> NA | T29: =IF(J29="NA","NA",_xlfn.XLOOKUP(TRIM(J29),nacionalidad!A:A,nacionalidad!B:B,"Por verificar")) -> NA | U29: =IF(K29="NA","NA",_xlfn.XLOOKUP(TRIM(K29),nacionalidad!A:A,nacionalidad!B:B,"Por verificar")) -> NA | V29: =IF(L29="NA","NA",_xlfn.XLOOKUP(TRIM(L29),nacionalidad!A:A,nacionalidad!B:B,"Por verificar")) -> NA | W29: =IF(M29="NA","NA",_xlfn.XLOOKUP(TRIM(M29),nacionalidad!A:A,nacionalidad!B:B,"Por verificar")) -> NA | ... Y29: =IF(O29="NA","NA",_xlfn.XLOOKUP(TRIM(O29),nacionalidad!A:A,nacionalidad!B:B,"Por verificar")) -> NA | Z29: Gil | AA29: Sony Music Latin | AB29: 17 | AC29: 20 | AD29: 6 | AE29: 815243
A30: Argentina | B30: 45967 | C30: noviembre_2025 | D30: 29 | E30: Yan Block, Panda Black | F30: Yan Block | G30: Panda Black | H30: NA | I30: NA | J30: NA | K30: NA | L30: NA | M30: NA | N30: NA | O30: NA | P30: =IF(F30="NA","NA",_xlfn.XLOOKUP(TRIM(F30),nacionalidad!A:A,nacionalidad!B:B,"Por verificar")) -> Puerto Rico | Q30: =IF(G30="NA","NA",_xlfn.XLOOKUP(TRIM(G30),nacionalidad!A:A,nacionalidad!B:B,"Por verificar")) -> Puerto Rico | R30: =IF(H30="NA","NA",_xlfn.XLOOKUP(TRIM(H30),nacionalidad!A:A,nacionalidad!B:B,"Por verificar")) -> NA | S30: =IF(I30="NA","NA",_xlfn.XLOOKUP(TRIM(I30),nacionalidad!A:A,nacionalidad!B:B,"Por verificar")) -> NA | T30: =IF(J30="NA","NA",_xlfn.XLOOKUP(TRIM(J30),nacionalidad!A:A,nacionalidad!B:B,"Por verificar")) -> NA | U30: =IF(K30="NA","NA",_xlfn.XLOOKUP(TRIM(K30),nacionalidad!A:A,nacionalidad!B:B,"Por verificar")) -> NA | V30: =IF(L30="NA","NA",_xlfn.XLOOKUP(TRIM(L30),nacionalidad!A:A,nacionalidad!B:B,"Por verificar")) -> NA | W30: =IF(M30="NA","NA",_xlfn.XLOOKUP(TRIM(M30),nacionalidad!A:A,nacionalidad!B:B,"Por verificar")) -> NA | ... Y30: =IF(O30="NA","NA",_xlfn.XLOOKUP(TRIM(O30),nacionalidad!A:A,nacionalidad!B:B,"Por verificar")) -> NA | Z30: 444 | AA30: SONAR LLC. | AB30: 25 | AC30: 33 | AD30: 39 | AE30: 812654
A31: Argentina | B31: 45967 | C31: noviembre_2025 | D31: 30 | E31: TINI | F31: TINI | G31: NA | H31: NA | I31: NA | J31: NA | K31: NA | L31: NA | M31: NA | N31: NA | O31: NA | P31: =IF(F31="NA","NA",_xlfn.XLOOKUP(TRIM(F31),nacionalidad!A:A,nacionalidad!B:B,"Por verificar")) -> Argentina | Q31: =IF(G31="NA","NA",_xlfn.XLOOKUP(TRIM(G31),nacionalidad!A:A,nacionalidad!B:B,"Por verificar")) -> NA | R31: =IF(H31="NA","NA",_xlfn.XLOOKUP(TRIM(H31),nacionalidad!A:A,nacionalidad!B:B,"Por verificar")) -> NA | S31: =IF(I31="NA","NA",_xlfn.XLOOKUP(TRIM(I31),nacionalidad!A:A,nacionalidad!B:B,"Por verificar")) -> NA | T31: =IF(J31="NA","NA",_xlfn.XLOOKUP(TRIM(J31),nacionalidad!A:A,nacionalidad!B:B,"Por verificar")) -> NA | U31: =IF(K31="NA","NA",_xlfn.XLOOKUP(TRIM(K31),nacionalidad!A:A,nacionalidad!B:B,"Por verificar")) -> NA | V31: =IF(L31="NA","NA",_xlfn.XLOOKUP(TRIM(L31),nacionalidad!A:A,nacionalidad!B:B,"Por verificar")) -> NA | W31: =IF(M31="NA","NA",_xlfn.XLOOKUP(TRIM(M31),nacionalidad!A:A,nacionalidad!B:B,"Por verificar")) -> NA | ... Y31: =IF(O31="NA","NA",_xlfn.XLOOKUP(TRIM(O31),nacionalidad!A:A,nacionalidad!B:B,"Por verificar")) -> NA | Z31: Una Noche Más | AA31: 5020 Records | AB31: 27 | AC31: 28 | AD31: 4 | AE31: 812462
A32: Argentina | B32: 45967 | C32: noviembre_2025 | D32: 31 | E32: Bad Bunny, Ozuna, Farruko, Arcángel, Ñengo Flow, DJ Luian, Mambo Kingz | F32: Bad Bunny | G32: Ozuna | H32: Farruko | I32: Arcángel | J32: Ñengo Flow | K32: DJ Luian | L32: Mambo Kingz | M32: NA | N32: NA | O32: NA | P32: =IF(F32="NA","NA",_xlfn.XLOOKUP(TRIM(F32),nacionalidad!A:A,nacionalidad!B:B,"Por verificar")) -> Puerto Rico | Q32: =IF(G32="NA","NA",_xlfn.XLOOKUP(TRIM(G32),nacionalidad!A:A,nacionalidad!B:B,"Por verificar")) -> Puerto Rico | R32: =IF(H32="NA","NA",_xlfn.XLOOKUP(TRIM(H32),nacionalidad!A:A,nacionalidad!B:B,"Por verificar")) -> Puerto Rico | S32: =IF(I32="NA","NA",_xlfn.XLOOKUP(TRIM(I32),nacionalidad!A:A,nacionalidad!B:B,"Por verificar")) -> Puerto Rico | T32: =IF(J32="NA","NA",_xlfn.XLOOKUP(TRIM(J32),nacionalidad!A:A,nacionalidad!B:B,"Por verificar")) -> Puerto Rico | U32: =IF(K32="NA","NA",_xlfn.XLOOKUP(TRIM(K32),nacionalidad!A:A,nacionalidad!B:B,"Por verificar")) -> Puerto Rico | V32: =IF(L32="NA","NA",_xlfn.XLOOKUP(TRIM(L32),nacionalidad!A:A,nacionalidad!B:B,"Por verificar")) -> Puerto Rico | W32: =IF(M32="NA","NA",_xlfn.XLOOKUP(TRIM(M32),nacionalidad!A:A,nacionalidad!B:B,"Por verificar")) -> NA | ... Y32: =IF(O32="NA","NA",_xlfn.XLOOKUP(TRIM(O32),nacionalidad!A:A,nacionalidad!B:B,"Por verificar")) -> NA | Z32: Diles | AA32: Rimas Entertainment LLC | AB32: 25 | AC32: 25 | AD32: 93 | AE32: 810284
A33: Argentina | B33: 45967 | C33: noviembre_2025 | D33: 32 | E33: Rauw Alejandro, Bad Bunny | F33: Rauw Alejandro | G33: Bad Bunny | H33: NA | I33: NA | J33: NA | K33: NA | L33: NA | M33: NA | N33: NA | O33: NA | P33: =IF(F33="NA","NA",_xlfn.XLOOKUP(TRIM(F33),nacionalidad!A:A,nacionalidad!B:B,"Por verificar")) -> Puerto Rico | Q33: =IF(G33="NA","NA",_xlfn.XLOOKUP(TRIM(G33),nacionalidad!A:A,nacionalidad!B:B,"Por verificar")) -> Puerto Rico | R33: =IF(H33="NA","NA",_xlfn.XLOOKUP(TRIM(H33),nacionalidad!A:A,nacionalidad!B:B,"Por verificar")) -> NA | S33: =IF(I33="NA","NA",_xlfn.XLOOKUP(TRIM(I33),nacionalidad!A:A,nacionalidad!B:B,"Por verificar")) -> NA | T33: =IF(J33="NA","NA",_xlfn.XLOOKUP(TRIM(J33),nacionalidad!A:A,nacionalidad!B:B,"Por verificar")) -> NA | U33: =IF(K33="NA","NA",_xlfn.XLOOKUP(TRIM(K33),nacionalidad!A:A,nacionalidad!B:B,"Por verificar")) -> NA | V33: =IF(L33="NA","NA",_xlfn.XLOOKUP(TRIM(L33),nacionalidad!A:A,nacionalidad!B:B,"Por verificar")) -> NA | W33: =IF(M33="NA","NA",_xlfn.XLOOKUP(TRIM(M33),nacionalidad!A:A,nacionalidad!B:B,"Por verificar")) -> NA | ... Y33: =IF(O33="NA","NA",_xlfn.XLOOKUP(TRIM(O33),nacionalidad!A:A,nacionalidad!B:B,"Por verificar")) -> NA | Z33: Qué Pasaría... | AA33: Sony Music Latin/Duars Entertainment | AB33: 14 | AC33: 22 | AD33: 51 | AE33: 810026
A34: Argentina | B34: 45967 | C34: noviembre_2025 | D34: 33 | E34: Tiago PZK, Ke Personajes | F34: Tiago PZK | G34: Ke Personajes | H34: NA | I34: NA | J34: NA | K34: NA | L34: NA | M34: NA | N34: NA | O34: NA | P34: =IF(F34="NA","NA",_xlfn.XLOOKUP(TRIM(F34),nacionalidad!A:A,nacionalidad!B:B,"Por verificar")) -> Argentina | Q34: =IF(G34="NA","NA",_xlfn.XLOOKUP(TRIM(G34),nacionalidad!A:A,nacionalidad!B:B,"Por verificar")) -> Argentina | R34: =IF(H34="NA","NA",_xlfn.XLOOKUP(TRIM(H34),nacionalidad!A:A,nacionalidad!B:B,"Por verificar")) -> NA | S34: =IF(I34="NA","NA",_xlfn.XLOOKUP(TRIM(I34),nacionalidad!A:A,nacionalidad!B:B,"Por verificar")) -> NA | T34: =IF(J34="NA","NA",_xlfn.XLOOKUP(TRIM(J34),nacionalidad!A:A,nacionalidad!B:B,"Por verificar")) -> NA | U34: =IF(K34="NA","NA",_xlfn.XLOOKUP(TRIM(K34),nacionalidad!A:A,nacionalidad!B:B,"Por verificar")) -> NA | V34: =IF(L34="NA","NA",_xlfn.XLOOKUP(TRIM(L34),nacionalidad!A:A,nacionalidad!B:B,"Por verificar")) -> NA | W34: =IF(M34="NA","NA",_xlfn.XLOOKUP(TRIM(M34),nacionalidad!A:A,nacionalidad!B:B,"Por verificar")) -> NA | ... Y34: =IF(O34="NA","NA",_xlfn.XLOOKUP(TRIM(O34),nacionalidad!A:A,nacionalidad!B:B,"Por verificar")) -> NA | Z34: Piel | AA34: WEA Latina | AB34: 2 | AC34: 40 | AD34: 92 | AE34: 805683
A35: Argentina | B35: 45967 | C35: noviembre_2025 | D35: 34 | E35: Yan Block, TORRRES | F35: Yan Block | G35: TORRRES | H35: NA | I35: NA | J35: NA | K35: NA | L35: NA | M35: NA | N35: NA | O35: NA | P35: =IF(F35="NA","NA",_xlfn.XLOOKUP(TRIM(F35),nacionalidad!A:A,nacionalidad!B:B,"Por verificar")) -> Puerto Rico | Q35: =IF(G35="NA","NA",_xlfn.XLOOKUP(TRIM(G35),nacionalidad!A:A,nacionalidad!B:B,"Por verificar")) -> Puerto Rico | R35: =IF(H35="NA","NA",_xlfn.XLOOKUP(TRIM(H35),nacionalidad!A:A,nacionalidad!B:B,"Por verificar")) -> NA | S35: =IF(I35="NA","NA",_xlfn.XLOOKUP(TRIM(I35),nacionalidad!A:A,nacionalidad!B:B,"Por verificar")) -> NA | T35: =IF(J35="NA","NA",_xlfn.XLOOKUP(TRIM(J35),nacionalidad!A:A,nacionalidad!B:B,"Por verificar")) -> NA | U35: =IF(K35="NA","NA",_xlfn.XLOOKUP(TRIM(K35),nacionalidad!A:A,nacionalidad!B:B,"Por verificar")) -> NA | V35: =IF(L35="NA","NA",_xlfn.XLOOKUP(TRIM(L35),nacionalidad!A:A,nacionalidad!B:B,"Por verificar")) -> NA | W35: =IF(M35="NA","NA",_xlfn.XLOOKUP(TRIM(M35),nacionalidad!A:A,nacionalidad!B:B,"Por verificar")) -> NA | ... Y35: =IF(O35="NA","NA",_xlfn.XLOOKUP(TRIM(O35),nacionalidad!A:A,nacionalidad!B:B,"Por verificar")) -> NA | Z35: Yo sé | AA35: SONAR LLC. | AB35: 11 | AC35: 36 | AD35: 44 | AE35: 771312
A36: Argentina | B36: 45967 | C36: noviembre_2025 | D36: 35 | E36: Plan B | F36: Plan B | G36: NA | H36: NA | I36: NA | J36: NA | K36: NA | L36: NA | M36: NA | N36: NA | O36: NA | P36: =IF(F36="NA","NA",_xlfn.XLOOKUP(TRIM(F36),nacionalidad!A:A,nacionalidad!B:B,"Por verificar")) -> Puerto Rico | Q36: =IF(G36="NA","NA",_xlfn.XLOOKUP(TRIM(G36),nacionalidad!A:A,nacionalidad!B:B,"Por verificar")) -> NA | R36: =IF(H36="NA","NA",_xlfn.XLOOKUP(TRIM(H36),nacionalidad!A:A,nacionalidad!B:B,"Por verificar")) -> NA | S36: =IF(I36="NA","NA",_xlfn.XLOOKUP(TRIM(I36),nacionalidad!A:A,nacionalidad!B:B,"Por verificar")) -> NA | T36: =IF(J36="NA","NA",_xlfn.XLOOKUP(TRIM(J36),nacionalidad!A:A,nacionalidad!B:B,"Por verificar")) -> NA | U36: =IF(K36="NA","NA",_xlfn.XLOOKUP(TRIM(K36),nacionalidad!A:A,nacionalidad!B:B,"Por verificar")) -> NA | V36: =IF(L36="NA","NA",_xlfn.XLOOKUP(TRIM(L36),nacionalidad!A:A,nacionalidad!B:B,"Por verificar")) -> NA | W36: =IF(M36="NA","NA",_xlfn.XLOOKUP(TRIM(M36),nacionalidad!A:A,nacionalidad!B:B,"Por verificar")) -> NA | ... Y36: =IF(O36="NA","NA",_xlfn.XLOOKUP(TRIM(O36),nacionalidad!A:A,nacionalidad!B:B,"Por verificar")) -> NA | Z36: Es un Secreto | AA36: Pina Records | AB36: 28 | AC36: 34 | AD36: 156 | AE36: 766215
A37: Argentina | B37: 45967 | C37: noviembre_2025 | D37: 36 | E37: Emilia, TINI, Nicki Nicole | F37: Emilia | G37: TINI | H37: Nicki Nicole | I37: NA | J37: NA | K37: NA | L37: NA | M37: NA | N37: NA | O37: NA | P37: =IF(F37="NA","NA",_xlfn.XLOOKUP(TRIM(F37),nacionalidad!A:A,nacionalidad!B:B,"Por verificar")) -> Argentina | Q37: =IF(G37="NA","NA",_xlfn.XLOOKUP(TRIM(G37),nacionalidad!A:A,nacionalidad!B:B,"Por verificar")) -> Argentina | R37: =IF(H37="NA","NA",_xlfn.XLOOKUP(TRIM(H37),nacionalidad!A:A,nacionalidad!B:B,"Por verificar")) -> Argentina | S37: =IF(I37="NA","NA",_xlfn.XLOOKUP(TRIM(I37),nacionalidad!A:A,nacionalidad!B:B,"Por verificar")) -> NA | T37: =IF(J37="NA","NA",_xlfn.XLOOKUP(TRIM(J37),nacionalidad!A:A,nacionalidad!B:B,"Por verificar")) -> NA | U37: =IF(K37="NA","NA",_xlfn.XLOOKUP(TRIM(K37),nacionalidad!A:A,nacionalidad!B:B,"Por verificar")) -> NA | V37: =IF(L37="NA","NA",_xlfn.XLOOKUP(TRIM(L37),nacionalidad!A:A,nacionalidad!B:B,"Por verificar")) -> NA | W37: =IF(M37="NA","NA",_xlfn.XLOOKUP(TRIM(M37),nacionalidad!A:A,nacionalidad!B:B,"Por verificar")) -> NA | ... Y37: =IF(O37="NA","NA",_xlfn.XLOOKUP(TRIM(O37),nacionalidad!A:A,nacionalidad!B:B,"Por verificar")) -> NA | Z37: blackout 🧊 | AA37: Sony Music Latin | AB37: 1 | AC37: 44 | AD37: 33 | AE37: 747108
A38: Argentina | B38: 45967 | C38: noviembre_2025 | D38: 37 | E38: Plan B | F38: Plan B | G38: NA | H38: NA | I38: NA | J38: NA | K38: NA | L38: NA | M38: NA | N38: NA | O38: NA | P38: =IF(F38="NA","NA",_xlfn.XLOOKUP(TRIM(F38),nacionalidad!A:A,nacionalidad!B:B,"Por verificar")) -> Puerto Rico | Q38: =IF(G38="NA","NA",_xlfn.XLOOKUP(TRIM(G38),nacionalidad!A:A,nacionalidad!B:B,"Por verificar")) -> NA | R38: =IF(H38="NA","NA",_xlfn.XLOOKUP(TRIM(H38),nacionalidad!A:A,nacionalidad!B:B,"Por verificar")) -> NA | S38: =IF(I38="NA","NA",_xlfn.XLOOKUP(TRIM(I38),nacionalidad!A:A,nacionalidad!B:B,"Por verificar")) -> NA | T38: =IF(J38="NA","NA",_xlfn.XLOOKUP(TRIM(J38),nacionalidad!A:A,nacionalidad!B:B,"Por verificar")) -> NA | U38: =IF(K38="NA","NA",_xlfn.XLOOKUP(TRIM(K38),nacionalidad!A:A,nacionalidad!B:B,"Por verificar")) -> NA | V38: =IF(L38="NA","NA",_xlfn.XLOOKUP(TRIM(L38),nacionalidad!A:A,nacionalidad!B:B,"Por verificar")) -> NA | W38: =IF(M38="NA","NA",_xlfn.XLOOKUP(TRIM(M38),nacionalidad!A:A,nacionalidad!B:B,"Por verificar")) -> NA | ... Y38: =IF(O38="NA","NA",_xlfn.XLOOKUP(TRIM(O38),nacionalidad!A:A,nacionalidad!B:B,"Por verificar")) -> NA | Z38: Fronteo | AA38: Pina Records | AB38: 9 | AC38: 63 | AD38: 21 | AE38: 744733
A39: Argentina | B39: 45967 | C39: noviembre_2025 | D39: 38 | E39: Beéle, Ovy On The Drums | F39: Beéle | G39: Ovy On The Drums | H39: NA | I39: NA | J39: NA | K39: NA | L39: NA | M39: NA | N39: NA | O39: NA | P39: =IF(F39="NA","NA",_xlfn.XLOOKUP(TRIM(F39),nacionalidad!A:A,nacionalidad!B:B,"Por verificar")) -> Colombia | Q39: =IF(G39="NA","NA",_xlfn.XLOOKUP(TRIM(G39),nacionalidad!A:A,nacionalidad!B:B,"Por verificar")) -> Colombia | R39: =IF(H39="NA","NA",_xlfn.XLOOKUP(TRIM(H39),nacionalidad!A:A,nacionalidad!B:B,"Por verificar")) -> NA | S39: =IF(I39="NA","NA",_xlfn.XLOOKUP(TRIM(I39),nacionalidad!A:A,nacionalidad!B:B,"Por verificar")) -> NA | T39: =IF(J39="NA","NA",_xlfn.XLOOKUP(TRIM(J39),nacionalidad!A:A,nacionalidad!B:B,"Por verificar")) -> NA | U39: =IF(K39="NA","NA",_xlfn.XLOOKUP(TRIM(K39),nacionalidad!A:A,nacionalidad!B:B,"Por verificar")) -> NA | V39: =IF(L39="NA","NA",_xlfn.XLOOKUP(TRIM(L39),nacionalidad!A:A,nacionalidad!B:B,"Por verificar")) -> NA | W39: =IF(M39="NA","NA",_xlfn.XLOOKUP(TRIM(M39),nacionalidad!A:A,nacionalidad!B:B,"Por verificar")) -> NA | ... Y39: =IF(O39="NA","NA",_xlfn.XLOOKUP(TRIM(O39),nacionalidad!A:A,nacionalidad!B:B,"Por verificar")) -> NA | Z39: mi refe | AA39: 5020 Records | AB39: 20 | AC39: 21 | AD39: 44 | AE39: 724826
A40: Argentina | B40: 45967 | C40: noviembre_2025 | D40: 39 | E40: Beéle | F40: Beéle | G40: NA | H40: NA | I40: NA | J40: NA | K40: NA | L40: NA | M40: NA | N40: NA | O40: NA | P40: =IF(F40="NA","NA",_xlfn.XLOOKUP(TRIM(F40),nacionalidad!A:A,nacionalidad!B:B,"Por verificar")) -> Colombia | Q40: =IF(G40="NA","NA",_xlfn.XLOOKUP(TRIM(G40),nacionalidad!A:A,nacionalidad!B:B,"Por verificar")) -> NA | R40: =IF(H40="NA","NA",_xlfn.XLOOKUP(TRIM(H40),nacionalidad!A:A,nacionalidad!B:B,"Por verificar")) -> NA | S40: =IF(I40="NA","NA",_xlfn.XLOOKUP(TRIM(I40),nacionalidad!A:A,nacionalidad!B:B,"Por verificar")) -> NA | T40: =IF(J40="NA","NA",_xlfn.XLOOKUP(TRIM(J40),nacionalidad!A:A,nacionalidad!B:B,"Por verificar")) -> NA | U40: =IF(K40="NA","NA",_xlfn.XLOOKUP(TRIM(K40),nacionalidad!A:A,nacionalidad!B:B,"Por verificar")) -> NA | V40: =IF(L40="NA","NA",_xlfn.XLOOKUP(TRIM(L40),nacionalidad!A:A,nacionalidad!B:B,"Por verificar")) -> NA | W40: =IF(M40="NA","NA",_xlfn.XLOOKUP(TRIM(M40),nacionalidad!A:A,nacionalidad!B:B,"Por verificar")) -> NA | ... Y40: =IF(O40="NA","NA",_xlfn.XLOOKUP(TRIM(O40),nacionalidad!A:A,nacionalidad!B:B,"Por verificar")) -> NA | Z40: si te pillara | AA40: 5020 Records | AB40: 16 | AC40: 23 | AD40: 19 | AE40: 722748
A41: Argentina | B41: 45967 | C41: noviembre_2025 | D41: 40 | E41: Bad Bunny | F41: Bad Bunny | G41: NA | H41: NA | I41: NA | J41: NA | K41: NA | L41: NA | M41: NA | N41: NA | O41: NA | P41: =IF(F41="NA","NA",_xlfn.XLOOKUP(TRIM(F41),nacionalidad!A:A,nacionalidad!B:B,"Por verificar")) -> Puerto Rico | Q41: =IF(G41="NA","NA",_xlfn.XLOOKUP(TRIM(G41),nacionalidad!A:A,nacionalidad!B:B,"Por verificar")) -> NA | R41: =IF(H41="NA","NA",_xlfn.XLOOKUP(TRIM(H41),nacionalidad!A:A,nacionalidad!B:B,"Por verificar")) -> NA | S41: =IF(I41="NA","NA",_xlfn.XLOOKUP(TRIM(I41),nacionalidad!A:A,nacionalidad!B:B,"Por verificar")) -> NA | T41: =IF(J41="NA","NA",_xlfn.XLOOKUP(TRIM(J41),nacionalidad!A:A,nacionalidad!B:B,"Por verificar")) -> NA | U41: =IF(K41="NA","NA",_xlfn.XLOOKUP(TRIM(K41),nacionalidad!A:A,nacionalidad!B:B,"Por verificar")) -> NA | V41: =IF(L41="NA","NA",_xlfn.XLOOKUP(TRIM(L41),nacionalidad!A:A,nacionalidad!B:B,"Por verificar")) -> NA | W41: =IF(M41="NA","NA",_xlfn.XLOOKUP(TRIM(M41),nacionalidad!A:A,nacionalidad!B:B,"Por verificar")) -> NA | ... Y41: =IF(O41="NA","NA",_xlfn.XLOOKUP(TRIM(O41),nacionalidad!A:A,nacionalidad!B:B,"Por verificar")) -> NA | Z41: BAILE INoLVIDABLE | AA41: Rimas Entertainment LLC. | AB41: 1 | AC41: 32 | AD41: 44 | AE41: 716532
A42: Argentina | B42: 45967 | C42: noviembre_2025 | D42: 41 | E42: No Te Va Gustar, Juan Casanova | F42: No Te Va Gustar | G42: Juan Casanova | H42: NA | I42: NA | J42: NA | K42: NA | L42: NA | M42: NA | N42: NA | O42: NA | P42: =IF(F42="NA","NA",_xlfn.XLOOKUP(TRIM(F42),nacionalidad!A:A,nacionalidad!B:B,"Por verificar")) -> Uruguay | Q42: =IF(G42="NA","NA",_xlfn.XLOOKUP(TRIM(G42),nacionalidad!A:A,nacionalidad!B:B,"Por verificar")) -> Uruguay | R42: =IF(H42="NA","NA",_xlfn.XLOOKUP(TRIM(H42),nacionalidad!A:A,nacionalidad!B:B,"Por verificar")) -> NA | S42: =IF(I42="NA","NA",_xlfn.XLOOKUP(TRIM(I42),nacionalidad!A:A,nacionalidad!B:B,"Por verificar")) -> NA | T42: =IF(J42="NA","NA",_xlfn.XLOOKUP(TRIM(J42),nacionalidad!A:A,nacionalidad!B:B,"Por verificar")) -> NA | U42: =IF(K42="NA","NA",_xlfn.XLOOKUP(TRIM(K42),nacionalidad!A:A,nacionalidad!B:B,"Por verificar")) -> NA | V42: =IF(L42="NA","NA",_xlfn.XLOOKUP(TRIM(L42),nacionalidad!A:A,nacionalidad!B:B,"Por verificar")) -> NA | W42: =IF(M42="NA","NA",_xlfn.XLOOKUP(TRIM(M42),nacionalidad!A:A,nacionalidad!B:B,"Por verificar")) -> NA | ... Y42: =IF(O42="NA","NA",_xlfn.XLOOKUP(TRIM(O42),nacionalidad!A:A,nacionalidad!B:B,"Por verificar")) -> NA | Z42: Tan Lejos | AA42: Elefante Blanco | AB42: 28 | AC42: 35 | AD42: 171 | AE42: 711112
... A82: Argentina | B82: 45995 | C82: diciembre_2025 | D82: 31 | E82: ROSALÍA | F82: ROSALÍA | G82: NA | H82: NA | I82: NA | J82: NA | K82: NA | L82: NA | M82: NA | N82: NA | O82: NA | P82: =IF(F82="NA","NA",_xlfn.XLOOKUP(TRIM(F82),nacionalidad!A:A,nacionalidad!B:B,"Por verificar")) -> España | Q82: =IF(G82="NA","NA",_xlfn.XLOOKUP(TRIM(G82),nacionalidad!A:A,nacionalidad!B:B,"Por verificar")) -> NA | R82: =IF(H82="NA","NA",_xlfn.XLOOKUP(TRIM(H82),nacionalidad!A:A,nacionalidad!B:B,"Por verificar")) -> NA | S82: =IF(I82="NA","NA",_xlfn.XLOOKUP(TRIM(I82),nacionalidad!A:A,nacionalidad!B:B,"Por verificar")) -> NA | T82: =IF(J82="NA","NA",_xlfn.XLOOKUP(TRIM(J82),nacionalidad!A:A,nacionalidad!B:B,"Por verificar")) -> NA | U82: =IF(K82="NA","NA",_xlfn.XLOOKUP(TRIM(K82),nacionalidad!A:A,nacionalidad!B:B,"Por verificar")) -> NA | V82: =IF(L82="NA","NA",_xlfn.XLOOKUP(TRIM(L82),nacionalidad!A:A,nacionalidad!B:B,"Por verificar")) -> NA | W82: =IF(M82="NA","NA",_xlfn.XLOOKUP(TRIM(M82),nacionalidad!A:A,nacionalidad!B:B,"Por verificar")) -> NA | ... Y82: =IF(O82="NA","NA",_xlfn.XLOOKUP(TRIM(O82),nacionalidad!A:A,nacionalidad!B:B,"Por verificar")) -> NA | Z82: Sexo, Violencia y Llantas | AA82: Columbia | AB82: 31 | AC82: 160 | AD82: 4 | AE82: 814297
A83: Argentina | B83: 45995 | C83: diciembre_2025 | D83: 32 | E83: Yan Block, Panda Black | F83: Yan Block | G83: Panda Black | H83: NA | I83: NA | J83: NA | K83: NA | L83: NA | M83: NA | N83: NA | O83: NA | P83: =IF(F83="NA","NA",_xlfn.XLOOKUP(TRIM(F83),nacionalidad!A:A,nacionalidad!B:B,"Por verificar")) -> Puerto Rico | Q83: =IF(G83="NA","NA",_xlfn.XLOOKUP(TRIM(G83),nacionalidad!A:A,nacionalidad!B:B,"Por verificar")) -> Puerto Rico | R83: =IF(H83="NA","NA",_xlfn.XLOOKUP(TRIM(H83),nacionalidad!A:A,nacionalidad!B:B,"Por verificar")) -> NA | S83: =IF(I83="NA","NA",_xlfn.XLOOKUP(TRIM(I83),nacionalidad!A:A,nacionalidad!B:B,"Por verificar")) -> NA | T83: =IF(J83="NA","NA",_xlfn.XLOOKUP(TRIM(J83),nacionalidad!A:A,nacionalidad!B:B,"Por verificar")) -> NA | U83: =IF(K83="NA","NA",_xlfn.XLOOKUP(TRIM(K83),nacionalidad!A:A,nacionalidad!B:B,"Por verificar")) -> NA | V83: =IF(L83="NA","NA",_xlfn.XLOOKUP(TRIM(L83),nacionalidad!A:A,nacionalidad!B:B,"Por verificar")) -> NA | W83: =IF(M83="NA","NA",_xlfn.XLOOKUP(TRIM(M83),nacionalidad!A:A,nacionalidad!B:B,"Por verificar")) -> NA | ... Y83: =IF(O83="NA","NA",_xlfn.XLOOKUP(TRIM(O83),nacionalidad!A:A,nacionalidad!B:B,"Por verificar")) -> NA | Z83: 444 | AA83: SONAR LLC. | AB83: 24 | AC83: 31 | AD83: 43 | AE83: 764220
A84: Argentina | B84: 45995 | C84: diciembre_2025 | D84: 33 | E84: Taylor Swift | F84: Taylor Swift | G84: NA | H84: NA | I84: NA | J84: NA | K84: NA | L84: NA | M84: NA | N84: NA | O84: NA | P84: =IF(F84="NA","NA",_xlfn.XLOOKUP(TRIM(F84),nacionalidad!A:A,nacionalidad!B:B,"Por verificar")) -> Estados Unidos | Q84: =IF(G84="NA","NA",_xlfn.XLOOKUP(TRIM(G84),nacionalidad!A:A,nacionalidad!B:B,"Por verificar")) -> NA | R84: =IF(H84="NA","NA",_xlfn.XLOOKUP(TRIM(H84),nacionalidad!A:A,nacionalidad!B:B,"Por verificar")) -> NA | S84: =IF(I84="NA","NA",_xlfn.XLOOKUP(TRIM(I84),nacionalidad!A:A,nacionalidad!B:B,"Por verificar")) -> NA | T84: =IF(J84="NA","NA",_xlfn.XLOOKUP(TRIM(J84),nacionalidad!A:A,nacionalidad!B:B,"Por verificar")) -> NA | U84: =IF(K84="NA","NA",_xlfn.XLOOKUP(TRIM(K84),nacionalidad!A:A,nacionalidad!B:B,"Por verificar")) -> NA | V84: =IF(L84="NA","NA",_xlfn.XLOOKUP(TRIM(L84),nacionalidad!A:A,nacionalidad!B:B,"Por verificar")) -> NA | W84: =IF(M84="NA","NA",_xlfn.XLOOKUP(TRIM(M84),nacionalidad!A:A,nacionalidad!B:B,"Por verificar")) -> NA | ... Y84: =IF(O84="NA","NA",_xlfn.XLOOKUP(TRIM(O84),nacionalidad!A:A,nacionalidad!B:B,"Por verificar")) -> NA | Z84: The Fate of Ophelia | AA84: Taylor Swift | AB84: 2 | AC84: 34 | AD84: 9 | AE84: 759603
A85: Argentina | B85: 45995 | C85: diciembre_2025 | D85: 34 | E85: Jin | F85: Jin | G85: NA | H85: NA | I85: NA | J85: NA | K85: NA | L85: NA | M85: NA | N85: NA | O85: NA | P85: =IF(F85="NA","NA",_xlfn.XLOOKUP(TRIM(F85),nacionalidad!A:A,nacionalidad!B:B,"Por verificar")) -> Corea del Sur | Q85: =IF(G85="NA","NA",_xlfn.XLOOKUP(TRIM(G85),nacionalidad!A:A,nacionalidad!B:B,"Por verificar")) -> NA | R85: =IF(H85="NA","NA",_xlfn.XLOOKUP(TRIM(H85),nacionalidad!A:A,nacionalidad!B:B,"Por verificar")) -> NA | S85: =IF(I85="NA","NA",_xlfn.XLOOKUP(TRIM(I85),nacionalidad!A:A,nacionalidad!B:B,"Por verificar")) -> NA | T85: =IF(J85="NA","NA",_xlfn.XLOOKUP(TRIM(J85),nacionalidad!A:A,nacionalidad!B:B,"Por verificar")) -> NA | U85: =IF(K85="NA","NA",_xlfn.XLOOKUP(TRIM(K85),nacionalidad!A:A,nacionalidad!B:B,"Por verificar")) -> NA | V85: =IF(L85="NA","NA",_xlfn.XLOOKUP(TRIM(L85),nacionalidad!A:A,nacionalidad!B:B,"Por verificar")) -> NA | W85: =IF(M85="NA","NA",_xlfn.XLOOKUP(TRIM(M85),nacionalidad!A:A,nacionalidad!B:B,"Por verificar")) -> NA | ... Y85: =IF(O85="NA","NA",_xlfn.XLOOKUP(TRIM(O85),nacionalidad!A:A,nacionalidad!B:B,"Por verificar")) -> NA | Z85: Don’t Say You Love Me | AA85: BIGHIT MUSIC | AB85: 17 | AC85: 36 | AD85: 29 | AE85: 754945
A86: Argentina | B86: 45995 | C86: diciembre_2025 | D86: 35 | E86: Bad Bunny, Ozuna, Farruko, Arcángel, Ñengo Flow, DJ Luian, Mambo Kingz | F86: Bad Bunny | G86: Ozuna | H86: Farruko | I86: Arcángel | J86: Ñengo Flow | K86: DJ Luian | L86: Mambo Kingz | M86: NA | N86: NA | O86: NA | P86: =IF(F86="NA","NA",_xlfn.XLOOKUP(TRIM(F86),nacionalidad!A:A,nacionalidad!B:B,"Por verificar")) -> Puerto Rico | Q86: =IF(G86="NA","NA",_xlfn.XLOOKUP(TRIM(G86),nacionalidad!A:A,nacionalidad!B:B,"Por verificar")) -> Puerto Rico | R86: =IF(H86="NA","NA",_xlfn.XLOOKUP(TRIM(H86),nacionalidad!A:A,nacionalidad!B:B,"Por verificar")) -> Puerto Rico | S86: =IF(I86="NA","NA",_xlfn.XLOOKUP(TRIM(I86),nacionalidad!A:A,nacionalidad!B:B,"Por verificar")) -> Puerto Rico | T86: =IF(J86="NA","NA",_xlfn.XLOOKUP(TRIM(J86),nacionalidad!A:A,nacionalidad!B:B,"Por verificar")) -> Puerto Rico | U86: =IF(K86="NA","NA",_xlfn.XLOOKUP(TRIM(K86),nacionalidad!A:A,nacionalidad!B:B,"Por verificar")) -> Puerto Rico | V86: =IF(L86="NA","NA",_xlfn.XLOOKUP(TRIM(L86),nacionalidad!A:A,nacionalidad!B:B,"Por verificar")) -> Puerto Rico | W86: =IF(M86="NA","NA",_xlfn.XLOOKUP(TRIM(M86),nacionalidad!A:A,nacionalidad!B:B,"Por verificar")) -> NA | ... Y86: =IF(O86="NA","NA",_xlfn.XLOOKUP(TRIM(O86),nacionalidad!A:A,nacionalidad!B:B,"Por verificar")) -> NA | Z86: Diles | AA86: Rimas Entertainment LLC | AB86: 25 | AC86: 29 | AD86: 97 | AE86: 753410
A87: Argentina | B87: 45995 | C87: diciembre_2025 | D87: 36 | E87: Beéle, Ovy On The Drums | F87: Beéle | G87: Ovy On The Drums | H87: NA | I87: NA | J87: NA | K87: NA | L87: NA | M87: NA | N87: NA | O87: NA | P87: =IF(F87="NA","NA",_xlfn.XLOOKUP(TRIM(F87),nacionalidad!A:A,nacionalidad!B:B,"Por verificar")) -> Colombia | Q87: =IF(G87="NA","NA",_xlfn.XLOOKUP(TRIM(G87),nacionalidad!A:A,nacionalidad!B:B,"Por verificar")) -> Colombia | R87: =IF(H87="NA","NA",_xlfn.XLOOKUP(TRIM(H87),nacionalidad!A:A,nacionalidad!B:B,"Por verificar")) -> NA | S87: =IF(I87="NA","NA",_xlfn.XLOOKUP(TRIM(I87),nacionalidad!A:A,nacionalidad!B:B,"Por verificar")) -> NA | T87: =IF(J87="NA","NA",_xlfn.XLOOKUP(TRIM(J87),nacionalidad!A:A,nacionalidad!B:B,"Por verificar")) -> NA | U87: =IF(K87="NA","NA",_xlfn.XLOOKUP(TRIM(K87),nacionalidad!A:A,nacionalidad!B:B,"Por verificar")) -> NA | V87: =IF(L87="NA","NA",_xlfn.XLOOKUP(TRIM(L87),nacionalidad!A:A,nacionalidad!B:B,"Por verificar")) -> NA | W87: =IF(M87="NA","NA",_xlfn.XLOOKUP(TRIM(M87),nacionalidad!A:A,nacionalidad!B:B,"Por verificar")) -> NA | ... Y87: =IF(O87="NA","NA",_xlfn.XLOOKUP(TRIM(O87),nacionalidad!A:A,nacionalidad!B:B,"Por verificar")) -> NA | Z87: mi refe | AA87: 5020 Records | AB87: 20 | AC87: 26 | AD87: 48 | AE87: 752241
A88: Argentina | B88: 45995 | C88: diciembre_2025 | D88: 37 | E88: DobleP, Peipper, Locura Mix, VERNAZ | F88: DobleP | G88: Peipper | H88: Locura Mix | I88: VERNAZ | J88: NA | K88: NA | L88: NA | M88: NA | N88: NA | O88: NA | P88: =IF(F88="NA","NA",_xlfn.XLOOKUP(TRIM(F88),nacionalidad!A:A,nacionalidad!B:B,"Por verificar")) -> Argentina | Q88: =IF(G88="NA","NA",_xlfn.XLOOKUP(TRIM(G88),nacionalidad!A:A,nacionalidad!B:B,"Por verificar")) -> Argentina | R88: =IF(H88="NA","NA",_xlfn.XLOOKUP(TRIM(H88),nacionalidad!A:A,nacionalidad!B:B,"Por verificar")) -> Argentina | S88: =IF(I88="NA","NA",_xlfn.XLOOKUP(TRIM(I88),nacionalidad!A:A,nacionalidad!B:B,"Por verificar")) -> Argentina | T88: =IF(J88="NA","NA",_xlfn.XLOOKUP(TRIM(J88),nacionalidad!A:A,nacionalidad!B:B,"Por verificar")) -> NA | U88: =IF(K88="NA","NA",_xlfn.XLOOKUP(TRIM(K88),nacionalidad!A:A,nacionalidad!B:B,"Por verificar")) -> NA | V88: =IF(L88="NA","NA",_xlfn.XLOOKUP(TRIM(L88),nacionalidad!A:A,nacionalidad!B:B,"Por verificar")) -> NA | W88: =IF(M88="NA","NA",_xlfn.XLOOKUP(TRIM(M88),nacionalidad!A:A,nacionalidad!B:B,"Por verificar")) -> NA | ... Y88: =IF(O88="NA","NA",_xlfn.XLOOKUP(TRIM(O88),nacionalidad!A:A,nacionalidad!B:B,"Por verificar")) -> NA | Z88: PUTERÍ4 | AA88: DALE PLAY Records / Wesaisons Records | AB88: 37 | AC88: 41 | AD88: 4 | AE88: 739546
A89: Argentina | B89: 45995 | C89: diciembre_2025 | D89: 38 | E89: Zion & Lennox | F89: Zion & Lennox | G89: NA | H89: NA | I89: NA | J89: NA | K89: NA | L89: NA | M89: NA | N89: NA | O89: NA | P89: =IF(F89="NA","NA",_xlfn.XLOOKUP(TRIM(F89),nacionalidad!A:A,nacionalidad!B:B,"Por verificar")) -> Puerto Rico | Q89: =IF(G89="NA","NA",_xlfn.XLOOKUP(TRIM(G89),nacionalidad!A:A,nacionalidad!B:B,"Por verificar")) -> NA | R89: =IF(H89="NA","NA",_xlfn.XLOOKUP(TRIM(H89),nacionalidad!A:A,nacionalidad!B:B,"Por verificar")) -> NA | S89: =IF(I89="NA","NA",_xlfn.XLOOKUP(TRIM(I89),nacionalidad!A:A,nacionalidad!B:B,"Por verificar")) -> NA | T89: =IF(J89="NA","NA",_xlfn.XLOOKUP(TRIM(J89),nacionalidad!A:A,nacionalidad!B:B,"Por verificar")) -> NA | U89: =IF(K89="NA","NA",_xlfn.XLOOKUP(TRIM(K89),nacionalidad!A:A,nacionalidad!B:B,"Por verificar")) -> NA | V89: =IF(L89="NA","NA",_xlfn.XLOOKUP(TRIM(L89),nacionalidad!A:A,nacionalidad!B:B,"Por verificar")) -> NA | W89: =IF(M89="NA","NA",_xlfn.XLOOKUP(TRIM(M89),nacionalidad!A:A,nacionalidad!B:B,"Por verificar")) -> NA | ... Y89: =IF(O89="NA","NA",_xlfn.XLOOKUP(TRIM(O89),nacionalidad!A:A,nacionalidad!B:B,"Por verificar")) -> NA | Z89: La player (Bandolera) | AA89: WEA Latina | AB89: 12 | AC89: 39 | AD89: 75 | AE89: 736867
A90: Argentina | B90: 45995 | C90: diciembre_2025 | D90: 39 | E90: Milo j, Trueno | F90: Milo j | G90: Trueno | H90: NA | I90: NA | J90: NA | K90: NA | L90: NA | M90: NA | N90: NA | O90: NA | P90: =IF(F90="NA","NA",_xlfn.XLOOKUP(TRIM(F90),nacionalidad!A:A,nacionalidad!B:B,"Por verificar")) -> Argentina | Q90: =IF(G90="NA","NA",_xlfn.XLOOKUP(TRIM(G90),nacionalidad!A:A,nacionalidad!B:B,"Por verificar")) -> Argentina | R90: =IF(H90="NA","NA",_xlfn.XLOOKUP(TRIM(H90),nacionalidad!A:A,nacionalidad!B:B,"Por verificar")) -> NA | S90: =IF(I90="NA","NA",_xlfn.XLOOKUP(TRIM(I90),nacionalidad!A:A,nacionalidad!B:B,"Por verificar")) -> NA | T90: =IF(J90="NA","NA",_xlfn.XLOOKUP(TRIM(J90),nacionalidad!A:A,nacionalidad!B:B,"Por verificar")) -> NA | U90: =IF(K90="NA","NA",_xlfn.XLOOKUP(TRIM(K90),nacionalidad!A:A,nacionalidad!B:B,"Por verificar")) -> NA | V90: =IF(L90="NA","NA",_xlfn.XLOOKUP(TRIM(L90),nacionalidad!A:A,nacionalidad!B:B,"Por verificar")) -> NA | W90: =IF(M90="NA","NA",_xlfn.XLOOKUP(TRIM(M90),nacionalidad!A:A,nacionalidad!B:B,"Por verificar")) -> NA | ... Y90: =IF(O90="NA","NA",_xlfn.XLOOKUP(TRIM(O90),nacionalidad!A:A,nacionalidad!B:B,"Por verificar")) -> NA | Z90: Gil | AA90: Sony Music Latin | AB90: 17 | AC90: 45 | AD90: 10 | AE90: 730909
A91: Argentina | B91: 45995 | C91: diciembre_2025 | D91: 40 | E91: Babasonicos | F91: Babasonicos | G91: NA | H91: NA | I91: NA | J91: NA | K91: NA | L91: NA | M91: NA | N91: NA | O91: NA | P91: =IF(F91="NA","NA",_xlfn.XLOOKUP(TRIM(F91),nacionalidad!A:A,nacionalidad!B:B,"Por verificar")) -> Argentina | Q91: =IF(G91="NA","NA",_xlfn.XLOOKUP(TRIM(G91),nacionalidad!A:A,nacionalidad!B:B,"Por verificar")) -> NA | R91: =IF(H91="NA","NA",_xlfn.XLOOKUP(TRIM(H91),nacionalidad!A:A,nacionalidad!B:B,"Por verificar")) -> NA | S91: =IF(I91="NA","NA",_xlfn.XLOOKUP(TRIM(I91),nacionalidad!A:A,nacionalidad!B:B,"Por verificar")) -> NA | T91: =IF(J91="NA","NA",_xlfn.XLOOKUP(TRIM(J91),nacionalidad!A:A,nacionalidad!B:B,"Por verificar")) -> NA | U91: =IF(K91="NA","NA",_xlfn.XLOOKUP(TRIM(K91),nacionalidad!A:A,nacionalidad!B:B,"Por verificar")) -> NA | V91: =IF(L91="NA","NA",_xlfn.XLOOKUP(TRIM(L91),nacionalidad!A:A,nacionalidad!B:B,"Por verificar")) -> NA | W91: =IF(M91="NA","NA",_xlfn.XLOOKUP(TRIM(M91),nacionalidad!A:A,nacionalidad!B:B,"Por verificar")) -> NA | ... Y91: =IF(O91="NA","NA",_xlfn.XLOOKUP(TRIM(O91),nacionalidad!A:A,nacionalidad!B:B,"Por verificar")) -> NA | Z91: Irresponsables | AA91: Pop Art | AB91: 30 | AC91: 30 | AD91: 96 | AE91: 726945
A92: Argentina | B92: 45995 | C92: diciembre_2025 | D92: 41 | E92: Rauw Alejandro, Bad Bunny | F92: Rauw Alejandro | G92: Bad Bunny | H92: NA | I92: NA | J92: NA | K92: NA | L92: NA | M92: NA | N92: NA | O92: NA | P92: =IF(F92="NA","NA",_xlfn.XLOOKUP(TRIM(F92),nacionalidad!A:A,nacionalidad!B:B,"Por verificar")) -> Puerto Rico | Q92: =IF(G92="NA","NA",_xlfn.XLOOKUP(TRIM(G92),nacionalidad!A:A,nacionalidad!B:B,"Por verificar")) -> Puerto Rico | R92: =IF(H92="NA","NA",_xlfn.XLOOKUP(TRIM(H92),nacionalidad!A:A,nacionalidad!B:B,"Por verificar")) -> NA | S92: =IF(I92="NA","NA",_xlfn.XLOOKUP(TRIM(I92),nacionalidad!A:A,nacionalidad!B:B,"Por verificar")) -> NA | T92: =IF(J92="NA","NA",_xlfn.XLOOKUP(TRIM(J92),nacionalidad!A:A,nacionalidad!B:B,"Por verificar")) -> NA | U92: =IF(K92="NA","NA",_xlfn.XLOOKUP(TRIM(K92),nacionalidad!A:A,nacionalidad!B:B,"Por verificar")) -> NA | V92: =IF(L92="NA","NA",_xlfn.XLOOKUP(TRIM(L92),nacionalidad!A:A,nacionalidad!B:B,"Por verificar")) -> NA | W92: =IF(M92="NA","NA",_xlfn.XLOOKUP(TRIM(M92),nacionalidad!A:A,nacionalidad!B:B,"Por verificar")) -> NA | ... Y92: =IF(O92="NA","NA",_xlfn.XLOOKUP(TRIM(O92),nacionalidad!A:A,nacionalidad!B:B,"Por verificar")) -> NA | Z92: Qué Pasaría... | AA92: Sony Music Latin/Duars Entertainment | AB92: 14 | AC92: 53 | AD92: 55 | AE92: 722046
A93: Argentina | B93: 45995 | C93: diciembre_2025 | D93: 42 | E93: Airbag | F93: Airbag | G93: NA | H93: NA | I93: NA | J93: NA | K93: NA | L93: NA | M93: NA | N93: NA | O93: NA | P93: =IF(F93="NA","NA",_xlfn.XLOOKUP(TRIM(F93),nacionalidad!A:A,nacionalidad!B:B,"Por verificar")) -> Argentina | Q93: =IF(G93="NA","NA",_xlfn.XLOOKUP(TRIM(G93),nacionalidad!A:A,nacionalidad!B:B,"Por verificar")) -> NA | R93: =IF(H93="NA","NA",_xlfn.XLOOKUP(TRIM(H93),nacionalidad!A:A,nacionalidad!B:B,"Por verificar")) -> NA | S93: =IF(I93="NA","NA",_xlfn.XLOOKUP(TRIM(I93),nacionalidad!A:A,nacionalidad!B:B,"Por verificar")) -> NA | T93: =IF(J93="NA","NA",_xlfn.XLOOKUP(TRIM(J93),nacionalidad!A:A,nacionalidad!B:B,"Por verificar")) -> NA | U93: =IF(K93="NA","NA",_xlfn.XLOOKUP(TRIM(K93),nacionalidad!A:A,nacionalidad!B:B,"Por verificar")) -> NA | V93: =IF(L93="NA","NA",_xlfn.XLOOKUP(TRIM(L93),nacionalidad!A:A,nacionalidad!B:B,"Por verificar")) -> NA | W93: =IF(M93="NA","NA",_xlfn.XLOOKUP(TRIM(M93),nacionalidad!A:A,nacionalidad!B:B,"Por verificar")) -> NA | ... Y93: =IF(O93="NA","NA",_xlfn.XLOOKUP(TRIM(O93),nacionalidad!A:A,nacionalidad!B:B,"Por verificar")) -> NA | Z93: Nunca Lo Olvides | AA93: DALE PLAY Records | AB93: 40 | AC93: 44 | AD93: 54 | AE93: 717465
A94: Argentina | B94: 45995 | C94: diciembre_2025 | D94: 43 | E94: Héctor "El Father", Wisin & Yandel | F94: Héctor "El Father" | G94: Wisin & Yandel | H94: NA | I94: NA | J94: NA | K94: NA | L94: NA | M94: NA | N94: NA | O94: NA | P94: =IF(F94="NA","NA",_xlfn.XLOOKUP(TRIM(F94),nacionalidad!A:A,nacionalidad!B:B,"Por verificar")) -> Puerto Rico | Q94: =IF(G94="NA","NA",_xlfn.XLOOKUP(TRIM(G94),nacionalidad!A:A,nacionalidad!B:B,"Por verificar")) -> Puerto Rico | R94: =IF(H94="NA","NA",_xlfn.XLOOKUP(TRIM(H94),nacionalidad!A:A,nacionalidad!B:B,"Por verificar")) -> NA | S94: =IF(I94="NA","NA",_xlfn.XLOOKUP(TRIM(I94),nacionalidad!A:A,nacionalidad!B:B,"Por verificar")) -> NA | T94: =IF(J94="NA","NA",_xlfn.XLOOKUP(TRIM(J94),nacionalidad!A:A,nacionalidad!B:B,"Por verificar")) -> NA | U94: =IF(K94="NA","NA",_xlfn.XLOOKUP(TRIM(K94),nacionalidad!A:A,nacionalidad!B:B,"Por verificar")) -> NA | V94: =IF(L94="NA","NA",_xlfn.XLOOKUP(TRIM(L94),nacionalidad!A:A,nacionalidad!B:B,"Por verificar")) -> NA | W94: =IF(M94="NA","NA",_xlfn.XLOOKUP(TRIM(M94),nacionalidad!A:A,nacionalidad!B:B,"Por verificar")) -> NA | ... Y94: =IF(O94="NA","NA",_xlfn.XLOOKUP(TRIM(O94),nacionalidad!A:A,nacionalidad!B:B,"Por verificar")) -> NA | Z94: El Teléfono | AA94: Machete Music | AB94: 43 | AC94: 51 | AD94: 9 | AE94: 714781
...

Sheet nacionalidad
A1: artista_base | B1: nacionalidad_sugerida
A2: Bad Bunny | B2: Puerto Rico
A3: Beéle | B3: Colombia
A4: Fuerza Regida | B4: Mexico
A5: Ovy On The Drums | B5: Colombia
A6: Blessd | B6: Colombia
A7: Tito Double P | B7: Mexico
A8: Peso Pluma | B8: Mexico
A9: Jere Klein | B9: Chile
A10: El Bogueto | B10: Mexico
A11: Junior H | B11: Mexico
A12: Kris R. | B12: Colombia
... A280: Yves Tumor | B280: Estados Unidos
